输出什么?

```js
new Promise((resolve,reject) => {
  throw 1
}).then((res) => {
  console.log(res);
})
```

答案是直接报错

下面这个呢

```js
new Promise((resolve,reject) => {
  throw 1
}).then((res) => {
  console.log(res);
}).catch(err => {
    console.log(err)
})
```

答案是输出1

**promise 对象里面同步代码抛出的错误在没有通过 promise 的 catch 方法捕获时是会打印报错的（不会阻止 promise 外面代码的执行），但是不会传递到外面触发其他错误监听函数（比如 window.onerror 、try-catch 等）**